Workbook

Sheet KetQua_LinhKien
A1: SYM_NAME | B1: Reference | C1: Value | D1: Footprint | E1: Datasheet | F1: Description | G1: LCSC | H1: BA_ID | I1: BA_LINK | J1: BA_OPTION | K1: BA_PRICE | L1: PNLAB_PRICE
A2: ADC-HX710B-SOIC8-0-Standard | B2: U | C2: HX710B | D2: EagleCad_kicad:SOIC_8 | E2: https://www.lcsc.com/datasheet/C78447.pdf | F2: HX710B SOIC-8 Analog to Digital Converters (ADC) ROHS | G2: C78447
A3: BUCK-LM2596S-ADJ-3A-TI | B3: U | C3: LM2596SX-ADJ/NOPB | D3: EagleCad_kicad:TO-263-5_TabPin3 | E3: https://www.lcsc.com/product-detail/C29781.html?s_z=n_LM2596 | F3: LM2596SX-ADJ/NOPB Adjustable 1.23V to 37V 3A 150kHz Step-Down Voltage Regulator, TO-263 | G3: C29781
A4: BUCK_XL1509_3.3V_2A | B4: U | C4: XL1509-3.3E1 | D4: EagleCad_kicad:SOIC_8 | E4: https://www.lcsc.com/product-detail/C74193.html | F4: XL1509-3.3E1 SOIC-8 -40℃~+85℃ 1 150kHz 2A 2mA 3.3V 4.5V~40V Buck Buck Built-In Fixed No SOP-8 DC-DC Converters ROHS | G4: C74193
A5: BUCK_XL1509_5V_2A | B5: U | C5: XL1509-5.0 | D5: EagleCad_kicad:SOIC_8 | E5: https://www.lcsc.com/product-detail/C61063.html | F5: XL1509-5.0E1 SOIC-8 150kHz 2A 2mA 4.5V~40V 5V Buck | G5: C61063
A6: BUCK_XL1509_ADJ_2A | B6: U | C6: XL1509-ADJE1 | D6: EagleCad_kicad:SOIC_8 | E6: https://www.lcsc.com/product-detail/C74192.html | F6: XL1509-5.0E1 SOIC-8 150kHz 2A 2mA -40℃~+85℃ 1 1.23V~37V 127kHz~173kHz 2A 2mA 4.5V~40V Adjustable Buck Buck Built-In No SOIC-8 XLSEMI | G6: C74192 | H6: BA006E54EC | I6: https://item.taobao.com/item.htm?id=574765445441 | K6: 0.76
A7: BUZZER-0-Standard | B7: SP | D7: kxnStandard_Buzzer:BUZZER_DIP | F7: http://tme.vn/Product.aspx?id=1350&fbclid=IwAR3WkRn80nGAFLzmmyiHbpP-Aw4zQJPzX71ujfdfL40brutGDB1yhhfyKow#page=pro_info
A8: CAP_CERAMIC_0_Standard | B8: C | C8: 1uF | D8: EagleCad_kicad:KXN_C0603 | E8: https://jlcpcb.com/api/file/downloadByFileSystemAccessId/8556213788459761664 | F8: C0603 1uF 105 50V ±10% Ceramic X5R | G8: C15849
A9: CAP_Polarized_0_Standard | B9: C | C9: 100uF | D9: EagleCad_kicad:RCL_PANASONIC_D | E9: https://jlcpcb.com/api/file/downloadByFileSystemAccessId/8590454605819129856 | F9: VT100UF16V167RV0124 100UF 16V ±20% SMD,D6.3xL5.4mm -55℃~+105℃ Aluminum Electrolytic Capacitors - SMD ROHS | G9: C5246579
A10: COMP-LM358 | B10: U | C10: LM358ADR | D10: EagleCad_kicad:SOIC_8 | E10: https://www.lcsc.com/product-detail/C74525.html | F10: Opam SOP-8 LM358ADR TI Vin 3-30V 3mV 700kHz TI | G10: C74525 | L10: 2150
A11: COMP-LM358_2_0
A12: COMP-LM358_3_0
A13: COMP-LM393 | B13: U | C13: LM393DR | D13: EagleCad_kicad:SOIC_8 | E13: https://www.lcsc.com/product-detail/C67470.html | F13: LM393DR SOIC-8 1.3us 2 25nA 2mV 400uA TTL Comparators ROHS | G13: C67470 | H13: BA006FBA3B | I13: https://item.taobao.com/item.htm?id=528647070337&skuId=6055794707724 | J13: LM393DR贴片 (TI) | K13: 0.3
A14: COMP-LM393_2_0
A15: COMP-LM393_3_0
A16: CONN-Audio-SMD-6P-3.5mm-4Ring-PJ-3420-A-C319102 | B16: J | C16: PJ-3420-A-C319102 | D16: EagleCad_kicad:CONN-Jack_3.5mm_PJ311_Horizontal | E16: https://www.lcsc.com/product-detail/C319102.html?s_z=n_PJ-3420-A | F16: PJ-3420-A-SMT 3.5mm Headphone Jack 0.5A 30V Surface Mount- Mic-G-R-L | G16: C319102 | H16: BA006BA9C1 | I16: https://item.taobao.com/item.htm?id=742689790413 | K16: 1.27
A17: CONN-Ipex-RF_U.FL-BWU.FL-IPEX1 | B17: J | C17: BWU.FL-IPEX1 | D17: EagleCad_kicad:IPEX-SMD_BWIPX-1-001E | E17: https://www.lcsc.com/product-detail/C5137195.html?s_z=n_BAT%2520WIRELESS%2520BWU.FL-IPEX1 | F17: BWU.FL-IPEX1 Connector Receptacle IPEX Male Pin 50Ω Surface Mount | G17: C5137195 | H17: BA0068DF4A | I17: https://item.taobao.com/item.htm?id=529673949109 | K17: 0.1 | L17: 550
A18: CONN-PS2-Adaptor | B18: H | C18: CONN-PS2 | D18: EagleCad_kicad:CONN-PS2-PLAYSTATION
A19: CONN-SMA-KE-90 | B19: J | C19: SMA-KWE弯角内孔(90度弯) | D19: EagleCad_kicad:CONN-SMA | F19: SMA-KWE弯角内孔(90度弯) | H19: BA006FA63F | I19: https://item.taobao.com/item.htm?id=529673697495&skuId=4051037650598 | J19: SMA-KWE弯角内孔(90度弯) | K19: 0.78
A20: CONN-SMA-KWE-90 | B20: J | C20: SMA-KWE弯角内孔(90度弯) | D20: EagleCad_kicad:CONN-SMA | F20: SMA-KWE弯角内孔(90度弯) | H20: BA006FB7C4 | I20: https://item.taobao.com/item.htm?id=529673697495&skuId=4051037650598 | J20: SMA-KWE弯角内孔(90度弯) | K20: 0.78
A21: CONN-SMD-EDGE-microbit-40P-Horizontal-Black | B21: J | C21: mi-H-Black | D21: EagleCad_kicad:CONN-SMD-microbit-nam | E21: https://item.taobao.com/item.htm?id=599309272242&skuId=4187482509230 | F21: microbit Horizontal Socket Connector (nam ngang black)
A22: CONN-SMD-EDGE-microbit-40P-Horizontal-Yellow | B22: J | C22: mi-H-Yellow | D22: EagleCad_kicad:CONN-SMD-microbit-nam | E22: https://item.taobao.com/item.htm?id=599309272242&skuId=4187482509236 | F22: microbit Horizontal Socket Connector (nam ngang yellow) | H22: BA006BB3FF | I22: https://item.taobao.com/item.htm?id=599309272242&skuId=4187482509236 | J22: 黄色 - 卧式 | K22: 4.85
A23: CONN-SMD-EDGE-microbit-40P-Vertical-Black | B23: J | C23: mi-V-Black | D23: EagleCad_kicad:CONN-SMD-microbit-dung | E23: https://item.taobao.com/item.htm?id=599309272242&skuId=4187482509229 | F23: microbit Vertical Socket Connector (dung Black)
A24: CONN-USB-A-FEMALE | B24: J | C24: USB_A | D24: EagleCad_kicad:CONN-USBAF | F24: 3D tren Kit CH32X035 OK
A25: CONN-USB-B-Micro_C456008 | B25: J | C25: MICRO-4P-DIP | D25: EagleCad_kicad:USB_Micro-B_kxn_C319160 | E25: https://www.lcsc.com/product-detail/C456008.html?s_z=n_USB-Micro | F25: USB Micro Type B connector, CONN RCPT USB 2.0 Micro-B 5POS SMD R/A | G25: C456008 | H25: BA006BB774 | I25: https://item.taobao.com/item.htm?id=538147501606&skuId=5937546427295 | J25: Micro-母座_牛角_无边 | K25: 0.17
A26: CONN-USB_C_Receptacle_USB2.0_16P | B26: J | C26: USB_C_16P | D26: EagleCad_kicad:USB_C_Receptacle_XKB_U262-16XN-4BVC11 | E26: https://www.lcsc.com/product-detail/C393939.html | F26: USB 16P Type-C Receptacle connector 30V 3A Black Female Surface Mount, Right Angle Type-C USB 3.1 SMD USB Connectors ROHS | G26: C393939 | H26: BA0068C9EC | I26: https://item.taobao.com/item.htm?id=573090887123&skuId=5770750381254 | J26: Type-C母座_16P_4脚插板_黑色 | K26: 0.17 | L26: 870
A27: CONN-USB_C_Receptacle_USB2.0_16P_0_0
A28: CONN_DOMINO_2P_0_Standard | B28: H | C28: 2P 3.81mm | D28: EagleCad_kicad:H381_2L_FIX | F28: DOMINO 3.81MM CHÂN CONG(DIMENSION 2 PIN:3.81MM)
A29: CONN_DOMINO_3P_0_Standard | B29: H | C29: 2P 3.81mm | D29: EagleCad_kicad:H381_2L_FIX | F29: DOMINO 3.81MM CHÂN CONG(DIMENSION 2 PIN:3.81MM)
A30: DIOD_DO-220AA-SMP-SS1P3L-M3/84A-30V_1.5A | B30: D | C30: SS1P3L-M3/84A | D30: EagleCad_kicad:D-DO220AAL-SMP | E30: https://www.lcsc.com/product-detail/C2875475.html?s_z=n_ss1p3L | F30: SS1P3L-M3/84A DIODE SCHOTTKY 30V DO-220AA(SMP) 1.5A | G30: C2875475 | H30: BA0089F247 | I30: https://item.taobao.com/item.htm?id=1028490266957 | K30: 0.38
A31: DIOD_SS34_SMA_40V_3A | B31: D | C31: SS34 | D31: EagleCad_kicad:Diod-SMA | E31: https://www.lcsc.com/product-detail/C8678.html | F31: DIODE SS34 SMA MDD 3A 40V 500uA@40V 550mV@3A Independent SMA(DO-214AC) Schottky Diodes ROHS | G31: C8678 | H31: BA0068D64B | I31: https://item.taobao.com/item.htm?id=545422120963 | K31: 0.2 | L31: 690
A32: DIOD_SS54_SMA_40V_5A-MDD | B32: D | C32: SS54 | D32: EagleCad_kicad:Diod-SMA | E32: https://www.lcsc.com/product-detail/C22452.html?s_z=n_ss54 | F32: DIODE SS54 SMA MDD 5A 40V Independent SMA(DO-214AC) Schottky Diodes ROHS | G32: C22452
A33: Diode-1N4001 | B33: D | C33: Diode-1N4001 | D33: Diode_THT:D_DO-41_SOD81_P10.16mm_Horizontal | E33: http://www.vishay.com/docs/88503/1n4001.pdf | F33: 50V 1A General Purpose Rectifier Diode, DO-41
A34: Diode-SOT23-BAT54A | B34: D | C34: BAT54A | D34: EagleCad_kicad:SOT-23 | E34: https://www.lcsc.com/product-detail/C916423.html | F34: BAT54A KL2 Schottky Diodes SOT23 | G34: C916423 | H34: BA0068C374
A35: Diode-SOT23-BAT54C | B35: D | C35: KL3 | D35: EagleCad_kicad:SOT-23 | E35: https://www.lcsc.com/product-detail/C916424.html?s_z=n_BAT54C | F35: BAT54C KL3 Schottky Diodes SOT23 | G35: C916424 | H35: BA0068C386
A36: Diode-TVS-Bi-SM712-SOT23 | B36: D | C36: SM712-02HTG | D36: EagleCad_kicad:SOT-23 | E36: https://wmsc.lcsc.com/wmsc/upload/file/pdf/v2/lcsc/2308281515_hongjiacheng-SM712_C7420375.pdf | F36: SM712-02HTG 19A@8/20us 600W@8/20us Bidirectional SOT-23 TVS Diodes RoHS | G36: C172881 | H36: BA0068C3F0
A37: Diode-TVS-Bi-SMAJ12CA | B37: D | C37: SMAJ12CA | D37: EagleCad_kicad:SMA | E37: https://www.lcsc.com/product-detail/C83267.html?s_z=n_SMAJ12CA | F37: SMAJ12CA Littelfuse 20.1A 19.9V 400W 13.3V Bidirectional 12V SMA ESD and Surge Protection (TVS/ESD) ROHS | G37: C83267 | H37: BA0068C401
A38: Diode-TVS-LESD5D5.0CT1G-SOD-523 | B38: D1 | C38: LESD5D5.0CT1G | D38: EagleCad_kicad:D_SOD-523 | E38: https://www.lcsc.com/product-detail/C5199850.html?s_z=n_LESD5D5.0CT1G | F38: LESD5D5.0CT1G 9.4A@8/20us 18.6V 7.8V 5V SOD-523 TVS Diodes RoHS | G38: C5199850 | H38: BA0068C41F | I38: https://item.taobao.com/item.htm?id=893986185841 | K38: 0.05 | L38: 380
A39: Diode-TVS-LESD5D5.0CT1G-SOD-523_0_0
A40: Diode-TVS-SRV05-4-N-BORN | B40: U | C40: SRV05-4-N | D40: EagleCad_kicad:SOT-23-6_L2.9-W1.6-P0.95-LS2.8-BL-1 | E40: https://www.lcsc.com/product-detail/C316033.html?s_z=n_SRV05 | F40: SRV05-4-N V5L-BORN ESD Protection Diodes with Low Clamping Voltage, SOT-23-6 | G40: C316033
...

Sheet Sheet1
A1: SYM_NAME | B1: Reference | C1: Value | D1: Footprint | E1: Datasheet | F1: Description | G1: LCSC | H1: BA_ID | I1: BA_LINK | J1: BA_OPTION | K1: BA_PRICE | L1: PNLAB_PRICE
A2: =IF(KetQua_LinhKien!A2<>"",KetQua_LinhKien!A2,"") -> ADC-HX710B-SOIC8-0-Standard | B2: =IF(KetQua_LinhKien!B2<>"",KetQua_LinhKien!B2,"") -> U | C2: =IF(KetQua_LinhKien!C2<>"",KetQua_LinhKien!C2,"") -> HX710B | D2: =IF(KetQua_LinhKien!D2<>"",KetQua_LinhKien!D2,"") -> EagleCad_kicad:SOIC_8 | E2: =IF(KetQua_LinhKien!E2<>"",KetQua_LinhKien!E2,"") -> https://www.lcsc.com/datasheet/C78447.pdf | F2: =IF(KetQua_LinhKien!F2<>"",KetQua_LinhKien!F2,"") -> HX710B SOIC-8 Analog to Digital Converters (ADC) ROHS | G2: =IF(KetQua_LinhKien!G2<>"",KetQua_LinhKien!G2,"") -> C78447 | H2: =IF(KetQua_LinhKien!H2<>"",KetQua_LinhKien!H2,"") | ... L2: =IF(KetQua_LinhKien!L2<>"",KetQua_LinhKien!L2,"")
A3: =IF(KetQua_LinhKien!A3<>"",KetQua_LinhKien!A3,"") -> BUCK-LM2596S-ADJ-3A-TI | B3: =IF(KetQua_LinhKien!B3<>"",KetQua_LinhKien!B3,"") -> U | C3: =IF(KetQua_LinhKien!C3<>"",KetQua_LinhKien!C3,"") -> LM2596SX-ADJ/NOPB | D3: =IF(KetQua_LinhKien!D3<>"",KetQua_LinhKien!D3,"") -> EagleCad_kicad:TO-263-5_TabPin3 | E3: =IF(KetQua_LinhKien!E3<>"",KetQua_LinhKien!E3,"") -> https://www.lcsc.com/product-detail/C29781.html?s_z=n_LM2596 | F3: =IF(KetQua_LinhKien!F3<>"",KetQua_LinhKien!F3,"") -> LM2596SX-ADJ/NOPB Adjustable 1.23V to 37V 3A 150kHz Step-Down Voltage Regulator, TO-263 | G3: =IF(KetQua_LinhKien!G3<>"",KetQua_LinhKien!G3,"") -> C29781 | H3: =IF(KetQua_LinhKien!H3<>"",KetQua_LinhKien!H3,"") | ... L3: =IF(KetQua_LinhKien!L3<>"",KetQua_LinhKien!L3,"")
A4: =IF(KetQua_LinhKien!A4<>"",KetQua_LinhKien!A4,"") -> BUCK_XL1509_3.3V_2A | B4: =IF(KetQua_LinhKien!B4<>"",KetQua_LinhKien!B4,"") -> U | C4: =IF(KetQua_LinhKien!C4<>"",KetQua_LinhKien!C4,"") -> XL1509-3.3E1 | D4: =IF(KetQua_LinhKien!D4<>"",KetQua_LinhKien!D4,"") -> EagleCad_kicad:SOIC_8 | E4: =IF(KetQua_LinhKien!E4<>"",KetQua_LinhKien!E4,"") -> https://www.lcsc.com/product-detail/C74193.html | F4: =IF(KetQua_LinhKien!F4<>"",KetQua_LinhKien!F4,"") -> XL1509-3.3E1 SOIC-8 -40℃~+85℃ 1 150kHz 2A 2mA 3.3V 4.5V~40V Buck Buck Built-In Fixed No SOP-8 DC-DC Converters ROHS | G4: =IF(KetQua_LinhKien!G4<>"",KetQua_LinhKien!G4,"") -> C74193 | H4: =IF(KetQua_LinhKien!H4<>"",KetQua_LinhKien!H4,"") | ... L4: =IF(KetQua_LinhKien!L4<>"",KetQua_LinhKien!L4,"")
A5: =IF(KetQua_LinhKien!A5<>"",KetQua_LinhKien!A5,"") -> BUCK_XL1509_5V_2A | B5: =IF(KetQua_LinhKien!B5<>"",KetQua_LinhKien!B5,"") -> U | C5: =IF(KetQua_LinhKien!C5<>"",KetQua_LinhKien!C5,"") -> XL1509-5.0 | D5: =IF(KetQua_LinhKien!D5<>"",KetQua_LinhKien!D5,"") -> EagleCad_kicad:SOIC_8 | E5: =IF(KetQua_LinhKien!E5<>"",KetQua_LinhKien!E5,"") -> https://www.lcsc.com/product-detail/C61063.html | F5: =IF(KetQua_LinhKien!F5<>"",KetQua_LinhKien!F5,"") -> XL1509-5.0E1 SOIC-8 150kHz 2A 2mA 4.5V~40V 5V Buck | G5: =IF(KetQua_LinhKien!G5<>"",KetQua_LinhKien!G5,"") -> C61063 | H5: =IF(KetQua_LinhKien!H5<>"",KetQua_LinhKien!H5,"") | ... L5: =IF(KetQua_LinhKien!L5<>"",KetQua_LinhKien!L5,"")
A6: =IF(KetQua_LinhKien!A6<>"",KetQua_LinhKien!A6,"") -> BUCK_XL1509_ADJ_2A | B6: =IF(KetQua_LinhKien!B6<>"",KetQua_LinhKien!B6,"") -> U | C6: =IF(KetQua_LinhKien!C6<>"",KetQua_LinhKien!C6,"") -> XL1509-ADJE1 | D6: =IF(KetQua_LinhKien!D6<>"",KetQua_LinhKien!D6,"") -> EagleCad_kicad:SOIC_8 | E6: =IF(KetQua_LinhKien!E6<>"",KetQua_LinhKien!E6,"") -> https://www.lcsc.com/product-detail/C74192.html | F6: =IF(KetQua_LinhKien!F6<>"",KetQua_LinhKien!F6,"") -> XL1509-5.0E1 SOIC-8 150kHz 2A 2mA -40℃~+85℃ 1 1.23V~37V 127kHz~173kHz 2A 2mA 4.5V~40V Adjustable Buck Buck Built-In No SOIC-8 XLSEMI | G6: =IF(KetQua_LinhKien!G6<>"",KetQua_LinhKien!G6,"") -> C74192 | H6: =IF(KetQua_LinhKien!H6<>"",KetQua_LinhKien!H6,"") -> BA006E54EC | ... L6: =IF(KetQua_LinhKien!L6<>"",KetQua_LinhKien!L6,"")
A7: =IF(KetQua_LinhKien!A7<>"",KetQua_LinhKien!A7,"") -> BUZZER-0-Standard | B7: =IF(KetQua_LinhKien!B7<>"",KetQua_LinhKien!B7,"") -> SP | C7: =IF(KetQua_LinhKien!C7<>"",KetQua_LinhKien!C7,"") | D7: =IF(KetQua_LinhKien!D7<>"",KetQua_LinhKien!D7,"") -> kxnStandard_Buzzer:BUZZER_DIP | E7: =IF(KetQua_LinhKien!E7<>"",KetQua_LinhKien!E7,"") | F7: =IF(KetQua_LinhKien!F7<>"",KetQua_LinhKien!F7,"") -> http://tme.vn/Product.aspx?id=1350&fbclid=IwAR3WkRn80nGAFLzmmyiHbpP-Aw4zQJPzX71ujfdfL40brutGDB1yhhfyKow#page=pro_info | G7: =IF(KetQua_LinhKien!G7<>"",KetQua_LinhKien!G7,"") | H7: =IF(KetQua_LinhKien!H7<>"",KetQua_LinhKien!H7,"") | ... L7: =IF(KetQua_LinhKien!L7<>"",KetQua_LinhKien!L7,"")
A8: =IF(KetQua_LinhKien!A8<>"",KetQua_LinhKien!A8,"") -> CAP_CERAMIC_0_Standard | B8: =IF(KetQua_LinhKien!B8<>"",KetQua_LinhKien!B8,"") -> C | C8: =IF(KetQua_LinhKien!C8<>"",KetQua_LinhKien!C8,"") -> 1uF | D8: =IF(KetQua_LinhKien!D8<>"",KetQua_LinhKien!D8,"") -> EagleCad_kicad:KXN_C0603 | E8: =IF(KetQua_LinhKien!E8<>"",KetQua_LinhKien!E8,"") -> https://jlcpcb.com/api/file/downloadByFileSystemAccessId/8556213788459761664 | F8: =IF(KetQua_LinhKien!F8<>"",KetQua_LinhKien!F8,"") -> C0603 1uF 105 50V ±10% Ceramic X5R | G8: =IF(KetQua_LinhKien!G8<>"",KetQua_LinhKien!G8,"") -> C15849 | H8: =IF(KetQua_LinhKien!H8<>"",KetQua_LinhKien!H8,"") | ... L8: =IF(KetQua_LinhKien!L8<>"",KetQua_LinhKien!L8,"")
A9: =IF(KetQua_LinhKien!A9<>"",KetQua_LinhKien!A9,"") -> CAP_Polarized_0_Standard | B9: =IF(KetQua_LinhKien!B9<>"",KetQua_LinhKien!B9,"") -> C | C9: =IF(KetQua_LinhKien!C9<>"",KetQua_LinhKien!C9,"") -> 100uF | D9: =IF(KetQua_LinhKien!D9<>"",KetQua_LinhKien!D9,"") -> EagleCad_kicad:RCL_PANASONIC_D | E9: =IF(KetQua_LinhKien!E9<>"",KetQua_LinhKien!E9,"") -> https://jlcpcb.com/api/file/downloadByFileSystemAccessId/8590454605819129856 | F9: =IF(KetQua_LinhKien!F9<>"",KetQua_LinhKien!F9,"") -> VT100UF16V167RV0124 100UF 16V ±20% SMD,D6.3xL5.4mm -55℃~+105℃ Aluminum Electrolytic Capacitors - SMD ROHS | G9: =IF(KetQua_LinhKien!G9<>"",KetQua_LinhKien!G9,"") -> C5246579 | H9: =IF(KetQua_LinhKien!H9<>"",KetQua_LinhKien!H9,"") | ... L9: =IF(KetQua_LinhKien!L9<>"",KetQua_LinhKien!L9,"")
A10: =IF(KetQua_LinhKien!A10<>"",KetQua_LinhKien!A10,"") -> COMP-LM358 | B10: =IF(KetQua_LinhKien!B10<>"",KetQua_LinhKien!B10,"") -> U | C10: =IF(KetQua_LinhKien!C10<>"",KetQua_LinhKien!C10,"") -> LM358ADR | D10: =IF(KetQua_LinhKien!D10<>"",KetQua_LinhKien!D10,"") -> EagleCad_kicad:SOIC_8 | E10: =IF(KetQua_LinhKien!E10<>"",KetQua_LinhKien!E10,"") -> https://www.lcsc.com/product-detail/C74525.html | F10: =IF(KetQua_LinhKien!F10<>"",KetQua_LinhKien!F10,"") -> Opam SOP-8 LM358ADR TI Vin 3-30V 3mV 700kHz TI | G10: =IF(KetQua_LinhKien!G10<>"",KetQua_LinhKien!G10,"") -> C74525 | H10: =IF(KetQua_LinhKien!H10<>"",KetQua_LinhKien!H10,"") | ... L10: =IF(KetQua_LinhKien!L10<>"",KetQua_LinhKien!L10,"") -> 2150
A11: =IF(KetQua_LinhKien!A11<>"",KetQua_LinhKien!A11,"") -> COMP-LM358_2_0 | B11: =IF(KetQua_LinhKien!B11<>"",KetQua_LinhKien!B11,"") | C11: =IF(KetQua_LinhKien!C11<>"",KetQua_LinhKien!C11,"") | D11: =IF(KetQua_LinhKien!D11<>"",KetQua_LinhKien!D11,"") | E11: =IF(KetQua_LinhKien!E11<>"",KetQua_LinhKien!E11,"") | F11: =IF(KetQua_LinhKien!F11<>"",KetQua_LinhKien!F11,"") | G11: =IF(KetQua_LinhKien!G11<>"",KetQua_LinhKien!G11,"") | H11: =IF(KetQua_LinhKien!H11<>"",KetQua_LinhKien!H11,"") | ... L11: =IF(KetQua_LinhKien!L11<>"",KetQua_LinhKien!L11,"")
A12: =IF(KetQua_LinhKien!A12<>"",KetQua_LinhKien!A12,"") -> COMP-LM358_3_0 | B12: =IF(KetQua_LinhKien!B12<>"",KetQua_LinhKien!B12,"") | C12: =IF(KetQua_LinhKien!C12<>"",KetQua_LinhKien!C12,"") | D12: =IF(KetQua_LinhKien!D12<>"",KetQua_LinhKien!D12,"") | E12: =IF(KetQua_LinhKien!E12<>"",KetQua_LinhKien!E12,"") | F12: =IF(KetQua_LinhKien!F12<>"",KetQua_LinhKien!F12,"") | G12: =IF(KetQua_LinhKien!G12<>"",KetQua_LinhKien!G12,"") | H12: =IF(KetQua_LinhKien!H12<>"",KetQua_LinhKien!H12,"") | ... L12: =IF(KetQua_LinhKien!L12<>"",KetQua_LinhKien!L12,"")
A13: =IF(KetQua_LinhKien!A13<>"",KetQua_LinhKien!A13,"") -> COMP-LM393 | B13: =IF(KetQua_LinhKien!B13<>"",KetQua_LinhKien!B13,"") -> U | C13: =IF(KetQua_LinhKien!C13<>"",KetQua_LinhKien!C13,"") -> LM393DR | D13: =IF(KetQua_LinhKien!D13<>"",KetQua_LinhKien!D13,"") -> EagleCad_kicad:SOIC_8 | E13: =IF(KetQua_LinhKien!E13<>"",KetQua_LinhKien!E13,"") -> https://www.lcsc.com/product-detail/C67470.html | F13: =IF(KetQua_LinhKien!F13<>"",KetQua_LinhKien!F13,"") -> LM393DR SOIC-8 1.3us 2 25nA 2mV 400uA TTL Comparators ROHS | G13: =IF(KetQua_LinhKien!G13<>"",KetQua_LinhKien!G13,"") -> C67470 | H13: =IF(KetQua_LinhKien!H13<>"",KetQua_LinhKien!H13,"") -> BA006FBA3B | ... L13: =IF(KetQua_LinhKien!L13<>"",KetQua_LinhKien!L13,"")
... A1000: =IF(KetQua_LinhKien!A1000<>"",KetQua_LinhKien!A1000,"") | B1000: =IF(KetQua_LinhKien!B1000<>"",KetQua_LinhKien!B1000,"") | C1000: =IF(KetQua_LinhKien!C1000<>"",KetQua_LinhKien!C1000,"") | D1000: =IF(KetQua_LinhKien!D1000<>"",KetQua_LinhKien!D1000,"") | E1000: =IF(KetQua_LinhKien!E1000<>"",KetQua_LinhKien!E1000,"") | F1000: =IF(KetQua_LinhKien!F1000<>"",KetQua_LinhKien!F1000,"") | G1000: =IF(KetQua_LinhKien!G1000<>"",KetQua_LinhKien!G1000,"") | H1000: =IF(KetQua_LinhKien!H1000<>"",KetQua_LinhKien!H1000,"") | ... L1000: =IF(KetQua_LinhKien!L1000<>"",KetQua_LinhKien!L1000,"")

Sheet Sheet2
A1: SYM_NAME | B1: Reference | C1: Value | D1: Footprint | E1: Datasheet | F1: Description | G1: LCSC | H1: BA_ID | I1: BA_LINK | J1: BA_OPTION | K1: BA_PRICE | L1: PNLAB_PRICE
A2: BUCK_XL1509_ADJ_2A | B2: U | C2: XL1509-ADJE1 | D2: EagleCad_kicad:SOIC_8 | E2: https://www.lcsc.com/product-detail/C74192.html | F2: XL1509-5.0E1 SOIC-8 150kHz 2A 2mA -40℃~+85℃ 1 1.23V~37V 127kHz~173kHz 2A 2mA 4.5V~40V Adjustable Buck Buck Built-In No SOIC-8 XLSEMI | G2: C74192 | H2: BA006E54EC | I2: https://item.taobao.com/item.htm?id=574765445441 | K2: 0.76 | M2: =COUNTIF($H$2:$H$196,H2) -> 1
A3: COMP-LM393 | B3: U | C3: LM393DR | D3: EagleCad_kicad:SOIC_8 | E3: https://www.lcsc.com/product-detail/C67470.html | F3: LM393DR SOIC-8 1.3us 2 25nA 2mV 400uA TTL Comparators ROHS | G3: C67470 | H3: BA006FBA3B | I3: https://item.taobao.com/item.htm?id=528647070337&skuId=6055794707724 | J3: LM393DR贴片 (TI) | K3: 0.3 | M3: =COUNTIF($H$2:$H$196,H3) -> 1
A4: CONN-Audio-SMD-6P-3.5mm-4Ring-PJ-3420-A-C319102 | B4: J | C4: PJ-3420-A-C319102 | D4: EagleCad_kicad:CONN-Jack_3.5mm_PJ311_Horizontal | E4: https://www.lcsc.com/product-detail/C319102.html?s_z=n_PJ-3420-A | F4: PJ-3420-A-SMT 3.5mm Headphone Jack 0.5A 30V Surface Mount- Mic-G-R-L | G4: C319102 | H4: BA006BA9C1 | I4: https://item.taobao.com/item.htm?id=742689790413 | K4: 1.27 | M4: =COUNTIF($H$2:$H$196,H4) -> 1
A5: CONN-Ipex-RF_U.FL-BWU.FL-IPEX1 | B5: J | C5: BWU.FL-IPEX1 | D5: EagleCad_kicad:IPEX-SMD_BWIPX-1-001E | E5: https://www.lcsc.com/product-detail/C5137195.html?s_z=n_BAT%2520WIRELESS%2520BWU.FL-IPEX1 | F5: BWU.FL-IPEX1 Connector Receptacle IPEX Male Pin 50Ω Surface Mount | G5: C5137195 | H5: BA0068DF4A | I5: https://item.taobao.com/item.htm?id=529673949109 | K5: 0.1 | L5: 550 | M5: =COUNTIF($H$2:$H$196,H5) -> 1
A6: CONN-SMA-KE-90 | B6: J | C6: SMA-KWE弯角内孔(90度弯) | D6: EagleCad_kicad:CONN-SMA | F6: SMA-KWE弯角内孔(90度弯) | H6: BA006FA63F | I6: https://item.taobao.com/item.htm?id=529673697495&skuId=4051037650598 | J6: SMA-KWE弯角内孔(90度弯) | K6: 0.78 | M6: =COUNTIF($H$2:$H$196,H6) -> 1
A7: CONN-SMA-KWE-90 | B7: J | C7: SMA-KWE弯角内孔(90度弯) | D7: EagleCad_kicad:CONN-SMA | F7: SMA-KWE弯角内孔(90度弯) | H7: BA006FB7C4 | I7: https://item.taobao.com/item.htm?id=529673697495&skuId=4051037650598 | J7: SMA-KWE弯角内孔(90度弯) | K7: 0.78 | M7: =COUNTIF($H$2:$H$196,H7) -> 1
A8: CONN-SMD-EDGE-microbit-40P-Horizontal-Yellow | B8: J | C8: mi-H-Yellow | D8: EagleCad_kicad:CONN-SMD-microbit-nam | E8: https://item.taobao.com/item.htm?id=599309272242&skuId=4187482509236 | F8: microbit Horizontal Socket Connector (nam ngang yellow) | H8: BA006BB3FF | I8: https://item.taobao.com/item.htm?id=599309272242&skuId=4187482509236 | J8: 黄色 - 卧式 | K8: 4.85 | M8: =COUNTIF($H$2:$H$196,H8) -> 1
A9: CONN-USB-B-Micro_C456008 | B9: J | C9: MICRO-4P-DIP | D9: EagleCad_kicad:USB_Micro-B_kxn_C319160 | E9: https://www.lcsc.com/product-detail/C456008.html?s_z=n_USB-Micro | F9: USB Micro Type B connector, CONN RCPT USB 2.0 Micro-B 5POS SMD R/A | G9: C456008 | H9: BA006BB774 | I9: https://item.taobao.com/item.htm?id=538147501606&skuId=5937546427295 | J9: Micro-母座_牛角_无边 | K9: 0.17 | M9: =COUNTIF($H$2:$H$196,H9) -> 1
A10: CONN-USB_C_Receptacle_USB2.0_16P | B10: J | C10: USB_C_16P | D10: EagleCad_kicad:USB_C_Receptacle_XKB_U262-16XN-4BVC11 | E10: https://www.lcsc.com/product-detail/C393939.html | F10: USB 16P Type-C Receptacle connector 30V 3A Black Female Surface Mount, Right Angle Type-C USB 3.1 SMD USB Connectors ROHS | G10: C393939 | H10: BA0068C9EC | I10: https://item.taobao.com/item.htm?id=573090887123&skuId=5770750381254 | J10: Type-C母座_16P_4脚插板_黑色 | K10: 0.17 | L10: 870 | M10: =COUNTIF($H$2:$H$196,H10) -> 1
A11: DIOD_DO-220AA-SMP-SS1P3L-M3/84A-30V_1.5A | B11: D | C11: SS1P3L-M3/84A | D11: EagleCad_kicad:D-DO220AAL-SMP | E11: https://www.lcsc.com/product-detail/C2875475.html?s_z=n_ss1p3L | F11: SS1P3L-M3/84A DIODE SCHOTTKY 30V DO-220AA(SMP) 1.5A | G11: C2875475 | H11: BA0089F247 | I11: https://item.taobao.com/item.htm?id=1028490266957 | K11: 0.38 | M11: =COUNTIF($H$2:$H$196,H11) -> 1
A12: DIOD_SS34_SMA_40V_3A | B12: D | C12: SS34 | D12: EagleCad_kicad:Diod-SMA | E12: https://www.lcsc.com/product-detail/C8678.html | F12: DIODE SS34 SMA MDD 3A 40V 500uA@40V 550mV@3A Independent SMA(DO-214AC) Schottky Diodes ROHS | G12: C8678 | H12: BA0068D64B | I12: https://item.taobao.com/item.htm?id=545422120963 | K12: 0.2 | L12: 690 | M12: =COUNTIF($H$2:$H$196,H12) -> 1
A13: Diode-TVS-LESD5D5.0CT1G-SOD-523 | B13: D1 | C13: LESD5D5.0CT1G | D13: EagleCad_kicad:D_SOD-523 | E13: https://www.lcsc.com/product-detail/C5199850.html?s_z=n_LESD5D5.0CT1G | F13: LESD5D5.0CT1G 9.4A@8/20us 18.6V 7.8V 5V SOD-523 TVS Diodes RoHS | G13: C5199850 | H13: BA0068C41F | I13: https://item.taobao.com/item.htm?id=893986185841 | K13: 0.05 | L13: 380 | M13: =COUNTIF($H$2:$H$196,H13) -> 1
A14: FET-N-AO4406-SOIC-8 | B14: Q | C14: AO4406AL | D14: EagleCad_kicad:SOIC_8 | E14: https://www.lcsc.com/product-detail/C35349.html | F14: N-Channel SOIC-8 30V 13A Single FETs, 2.5V@250uA , MOSFETs ROHS | G14: C35349 | H14: BA0068D437 | I14: https://item.taobao.com/item.htm?id=580476523099 | K14: 0.78 | M14: =COUNTIF($H$2:$H$196,H14) -> 1
A15: FET-N-BSS138-SOT23 | B15: Q | C15: BSS138LT1G | D15: EagleCad_kicad:SOT-23 | E15: https://www.lcsc.com/product-detail/C82045.html | F15: 50V Vds, 0.22A Id, N-Channel MOSFET, SOT-23 | G15: C82045 | H15: BA00709865 | I15: https://item.taobao.com/item.htm?id=536966002277&skuId=5115676055433 | J15: BSS138/J1 长电 (20个) | K15: 0.106 | L15: 740 | M15: =COUNTIF($H$2:$H$196,H15) -> 1
A16: FET-N-N-NDC7002N-SOT23-6 | B16: Q | C16: NDC7002N | D16: EagleCad_kicad:TSOT-23-6 | E16: https://www.lcsc.com/product-detail/C404322.html?s_z=n_nDC7002 | F16: NDC7002N 0.51A, Dual N-Channel MOSFET, SOT23-6 | G16: C404322 | H16: BA007F3733 | I16: https://item.taobao.com/item.htm?id=661363377160 | K16: 0.44 | M16: =COUNTIF($H$2:$H$196,H16) -> 1
A17: GSM-A7680C-LANS | B17: U | C17: A7680C-LANS | D17: EagleCad_kicad:GSM-A7680C-LCC-LAG_L17.6-W15.7 | E17: https://www.lcsc.com/product-detail/C5354934.html?s_z=n_7680c%2520GSM | F17: A7680C-LANS LCC-LAG-92_L17.6-W15.7 RF Transceiver Modules and Modems RoHS | G17: C5354934 | H17: BA0068A7FA | I17: https://item.taobao.com/item.htm?abbucket=20&id=683204374474&skuId=6096326990029 | J17: A7680C-LANS | K17: 23.5 | M17: =COUNTIF($H$2:$H$196,H17) -> 1
A18: HEADER-01x15-M-S-2.54mm-BLack | B18: J2 | C18: 1x15 Male Black | D18: EagleCad_kicad:HEADER_1X15_254 | E18: https://jlcpcb.com/api/file/downloadByFileSystemAccessId/8588889739995336704 | F18: 1X15 Male Header Black Straight (Thang) P=2.54mm Pin Headers ROHS | G18: C124381 | H18: BA00A6AF4B | I18: https://item.taobao.com/item.htm?id=610036472228&skuId=5663916729960 | J18: 1x15P (20个) - 单排直针 | K18: 0.106 | M18: =COUNTIF($H$2:$H$196,H18) -> 1
A19: HEADER_02x06_M_S_2.54mm_Black | B19: J | C19: HEADER_02x06_M_S_2.54mm_Black | D19: EagleCad_kicad:HEADER_2X6_254_SMD_Horizontal | F19: 2X06 Male Header Black Straight (Thang) P=2.54mm Pin Headers ROHS | H19: BA009493D2 | I19: https://item.taobao.com/item.htm?id=991099591240&skuId=5963845432860 | J19: 2*6P双排针(L12) | K19: 0.16 | M19: =COUNTIF($H$2:$H$196,H19) -> 1
A20: IC-CH340C-SOIC-16 | B20: U | C20: CH340C | D20: EagleCad_kicad:SO016 | E20: https://www.lcsc.com/product-detail/C84681.html | F20: Transceiver USB 2.0 SOP-16 Interface Controllers ROHS | G20: C84681 | H20: BA0089E77B | I20: https://item.taobao.com/item.htm?id=528686388349&skuId=4057187815714 | J20: CH340C/SOP-16 | K20: 1.75 | L20: 9100 | M20: =COUNTIF($H$2:$H$196,H20) -> 1
A21: IC-CH343P-TQFN-16-EP | B21: U4 | C21: CH343P | D21: EagleCad_kicad:TQFN-16-EP_KXN | E21: https://www.lcsc.com/product-detail/C2846043.html?s_z=n_ch343p | F21: USB to UART USB 2.0 TQFN-16-EP(3x3) Interface Controllers RoHS | G21: C2846043 | H21: BA00947B16 | I21: https://item.taobao.com/item.htm?id=683699633812 | K21: 3.76 | L21: 18050 | M21: =COUNTIF($H$2:$H$196,H21) -> 1
A22: IC-CS100A-SOIC-16 | B22: U | C22: CS100A | D22: EagleCad_kicad:SO016 | E22: https://item.taobao.com/item.htm?id=597036060496 | H22: BA0068F69A | I22: https://item.taobao.com/item.htm?id=597036060496 | K22: 1.1 | M22: =COUNTIF($H$2:$H$196,H22) -> 1
A23: IC-L9110S-Mixic-9V | B23: U | C23: L9110S-MIXIC | D23: EagleCad_kicad:SOIC_8 | E23: https://www.lcsc.com/product-detail/C513306.html?s_z=n_l9110s%2520mixic | F23: Phai MUA DUNG Mixic L9110S 3V~9V SOP-8 Motor Drivers, Controllers RoHS | H23: BA0096DA99 | I23: https://item.taobao.com/item.htm?id=522555135178 | K23: 0.52 | M23: =COUNTIF($H$2:$H$196,H23) -> 1
A24: IC-RTC-DS1307ZN+-SOIC-8 | B24: U1 | C24: DS1307ZN+T&R | D24: EagleCad_kicad:SOIC_8 | E24: https://www.lcsc.com/product-detail/C26858.html?s_z=n_DS1307ZN%252B | F24: MAXIM DS1307ZN+T&R 64 x 8, Serial, I2C Real-time clock, 4.5V to 5.5V VCC, SOIC-8 | G24: C26858 | H24: BA0068B62E | I24: https://www.lcsc.com/product-detail/C356706.html?s_z=n_q_ds1307 | K24: 1 | M24: =COUNTIF($H$2:$H$196,H24) -> 1
A25: LED-WS2812B | B25: D | C25: LED-WS2812B | D25: EagleCad_kicad:LED_WS2812B_PLCC4_5.0x5.0mm_P3.2mm | E25: https://www.lcsc.com/product-detail/C4154882.html | F25: WS2812B-XF02/W WS2812B 3V3 RGB LED 5.0x5.0mm_P3.2mm with integrated controller | G25: C4154882 | H25: BA00949D35 | I25: https://item.taobao.com/item.htm?id=925079788902&skuId=5970726835465 | J25: 5050幻彩铁支架 | K25: 0.04 | L25: 1430 | M25: =COUNTIF($H$2:$H$196,H25) -> 1
A26: MCU-AVR-ATMEGA2560AU-LQFP100 | B26: U | C26: ATMEGA2560AU-LQFP100 | D26: EagleCad_kicad:LQFP-100_14x14mm_P0.5mm | F26: MICROCONTROLLER\n\n64/128/256 Kbytes FLASH\n\n4 Kbytes EEPROM\n\n8 Kbytes SRAM\n\n86 General Purpose I/O pins\n\n12-channels16-bit PWM\n\n4 x Serial USARTs\n\n16-channels 10-bit A/D | H26: BA00A544BA | K26: 60.8 | M26: =COUNTIF($H$2:$H$196,H26) -> 1
A27: MCU-AVR-ATMEGA328P-32MUR-5x5-EP3.1mm | B27: IC3 | C27: 328P-MUR | D27: EagleCad_kicad:QFN-32-1EP_5x5mm_P0.5mm_EP3.1x3.1mm | E27: https://www.lcsc.com/product-detail/C7499261.html?s_z=n_atmega328P-MU | F27: ATMEGA328P-MU AVR 8 Bit 20MHz 23 VQFN-32(5x5) Microcontrollers RoHS | G27: C7499261 | H27: BA0089E1AF | I27: https://item.taobao.com/item.htm?id=569853049018 | K27: 9.7 | M27: =COUNTIF($H$2:$H$196,H27) -> 1
A28: MCU-PUYA-0-Standard-PY32F030K28U6TR-QFN32 | B28: U | C28: PY32F030K28U6TR | D28: EagleCad_kicad:QFN-32-1EP_5x5mm_P0.5mm_EP3.6x3.6mm | E28: https://www.lcsc.com/product-detail/C3018718.html?s_z=n_py32f030k28 | F28: PY32F030K28U6TR QFN-32-EP(5x5) Microcontrollers RoHS | G28: C3018718 | H28: BA0068A531 | I28: https://item.taobao.com/item.htm?abbucket=20&id=887798743862 | K28: 1.76 | M28: =COUNTIF($H$2:$H$196,H28) -> 1
A29: Module-GPS-GP-02 | B29: U | C29: GP-02 | D29: EagleCad_kicad:Module-GP-02_FULL_PAD | H29: BA0070947A | I29: https://item.taobao.com/item.htm?id=657924444300 | K29: 10.8 | M29: =COUNTIF($H$2:$H$196,H29) -> 1
A30: Module-RF-Ai-Thinker-Ra-01SH-ipex | B30: U | C30: Ra-01SH-ipex | D30: EagleCad_kicad:Module-RF-Ai-Thinker-Ra-01SH-LoRa | F30: Ra-01SH ipex version | H30: BA00710520 | I30: https://item.taobao.com/item.htm?id=670598562459&skuId=4994783990650 | J30: Ra-01SH贴IPEX | K30: 20.7 | M30: =COUNTIF($H$2:$H$196,H30) -> 1
A31: Module-RF-Ai-Thinker-Ra-02 | B31: U | C31: Ra-02 | D31: EagleCad_kicad:Module-RF-Ai-Thinker-Ra-02-LoRa | F31: Ai-Thinker Ra-02 | H31: BA0071075B | I31: https://item.taobao.com/item.htm?id=543372168003&skuId=4631718399751 | J31: Ra-02模块 | K31: 23.75 | M31: =COUNTIF($H$2:$H$196,H31) -> 1
A32: MuaKem-Jumper-2P-2.54mm-BLACK | B32: Buy | C32: JUMPER-2P-254-BLACK | F32: JUMPER 2P 2.54mm BLACK | H32: BA00949815 | I32: https://item.taobao.com/item.htm?id=530578115878&skuId=3255314001635 | J32: 2.54mm开口-(100个) | K32: 0.0138 | M32: =COUNTIF($H$2:$H$196,H32) -> 1
A33: RES-4R-N0603-1K | B33: RN | C33: RN0603-1K | D33: EagleCad_kicad:R_Cat16-4 | E33: https://www.lcsc.com/product-detail/C425239.html?s_z=n_4D03 | F33: 4D03WGF1001T5E Tolerance 1% 1kΩ 62.5mW 0603x4 Resistor Networks, Arrays RoHS | G33: C425239 | H33: BA0068E9B1 | I33: https://item.taobao.com/item.htm?id=522573249593&skuId=5718679317171 | J33: 1kΩ | K33: 0.0385 | M33: =COUNTIF($H$2:$H$196,H33) -> 1
A34: SENSOR-CNY70-DIP-TFK138 | B34: U | C34: CNY70 | D34: EagleCad_kicad:CNY70_IR | E34: https://item.taobao.com/item.htm?id=36003890048 | F34: CNY70 TFK138 Reflective Optical Sensor with Transistor Output | H34: BA0068F39B | I34: https://item.taobao.com/item.htm?abbucket=20&id=818193445983 | K34: 1.14 | M34: =COUNTIF($H$2:$H$196,H34) -> 1
A35: SENSOR-THT-DHT20-I2C-Aosong | B35: DHT | C35: DHT20 | D35: EagleCad_kicad:DHT20 | F35: DHT20 Aosong 16.1x12.6x6mm Temperature and Humidity Sensor ROHS | H35: BA008220E1 | I35: https://item.taobao.com/item.htm?id=993463290729&skuId=6135617994492 | J35: DHT20传感器 | K35: 3.63 | M35: =COUNTIF($H$2:$H$196,H35) -> 1
A36: SENSOR-ULTRASONIC_SPEAKER-TX | B36: SP | C36: ULTRA-TX | D36: EagleCad_kicad:ULTRASONIC_SPEAKER | E36: https://www.lcsc.com/product-detail/C17701106.html | F36: 16x12mm Ultrasonic Transmitters ROHS | G36: C17701106 | H36: BA0068F7AC | I36: https://item.taobao.com/item.htm?id=522575864004 | K36: 1.65 | M36: =COUNTIF($H$2:$H$196,H36) -> 1
A37: SOCKET-CR_BATTERRY_CR2032_DIP | B37: B | C37: KH-CR2032-2-1 | D37: EagleCad_kicad:CR2032-20MM | E37: https://www.lcsc.com/product-detail/C5365915.html?s_z=n_CR2032-2-1 | F37: KH-CR2032-2-1 De pin CR2032 DIP | G37: C5365915 | H37: BA0068B7EE | I37: https://item.taobao.com/item.htm?id=522572273679 | K37: 0.17 | L37: 2900 | M37: =COUNTIF($H$2:$H$196,H37) -> 1
A38: SW_PUSH_BUTTON_SMD_2P_3x2.5mm_Black-B3U-P1000 | B38: SW | C38: B3U-1000P | D38: EagleCad_kicad:Button-SW-SMD157SW | E38: https://www.lcsc.com/product-detail/C231329.html?s_z=n_B3u-1000p | F38: Tactile Switch SPST 153gf 1.6mm SMD (SMT) Tab 3mm x 2.5mm Surface Mount | G38: C231329 | H38: BA0089E6F6 | I38: https://item.taobao.com/item.htm?id=729682954733&skuId=5226875198084 | J38: B3U-1000P | K38: 0.5 | M38: =COUNTIF($H$2:$H$196,H38) -> 1
A39: Sensor-Air-MQ2-DIP | B39: U | C39: MQ2 | D39: EagleCad_kicad:Sensor-MQ2_3_6 | H39: BA007E1C68 | I39: https://item.taobao.com/item.htm?id=633891364709 | K39: 5.5 | M39: =COUNTIF($H$2:$H$196,H39) -> 1
A40: Sensor-MICRO-PHONE-9*7mm-50db | B40: U | C40: mic9*7 | D40: EagleCad_kicad:Sensor-MICRO_PHONE_9X7MM | H40: BA0081D381 | I40: https://item.taobao.com/item.htm?id=522579268136 | K40: 0.3 | M40: =COUNTIF($H$2:$H$196,H40) -> 1
...

Sheet Sheet3
A1: Mã SKU | B1: Tên nguyên vật liệu | C1: Đơn vị | D1: Tồn kho | E1: Tồn kho tối thiểu | F1: Giá nhập 1 | G1: Giá nhập 2 | H1: Loại sản phẩm | I1: Nhà cung cấp | J1: Link 1 | K1: Link 2 | L1: Ghi chú 1 | M1: Ghi chú 2 | N1: Ghi chú 3 | O1: Ghi chú 4 | P1: Tags | Q1: Hình ảnh
A2: =IF(Sheet2!H2<>"",Sheet2!H2,"") -> BA006E54EC | B2: =IF(Sheet2!A2<>"",Sheet2!A2,"") -> BUCK_XL1509_ADJ_2A | C2: Cái | D2: 0 | E2: 0 | F2: =IF(Sheet2!K2<>"",Sheet2!K2*3800,"") -> 2888 | G2: =IF(Sheet2!L2<>"",Sheet2!L2,"") | J2: =IF(Sheet2!I2<>"",Sheet2!I2,"") -> https://item.taobao.com/item.htm?id=574765445441 | L2: =IF(Sheet2!J2<>"",Sheet2!J2,"") | N2: =IF(Sheet2!E2<>"",Sheet2!E2,"") -> https://www.lcsc.com/product-detail/C74192.html | O2: =IF(Sheet2!G2<>"",Sheet2!G2,"") -> C74192 | P2: =IF(Sheet2!C2<>"",Sheet2!C2,"") -> XL1509-ADJE1 | Q2: ="https://github.com/Khuuxuanngoc/image_LK_ForWeb/blob/main/vnehciovn/"&A2&".jpg?raw=true" -> https://github.com/Khuuxuanngoc/image_LK_ForWeb/blob/main/vnehciovn/BA006E54EC.jpg?raw=true
A3: =IF(Sheet2!H3<>"",Sheet2!H3,"") -> BA006FBA3B | B3: =IF(Sheet2!A3<>"",Sheet2!A3,"") -> COMP-LM393 | C3: Cái | D3: 0 | E3: 0 | F3: =IF(Sheet2!K3<>"",Sheet2!K3*3800,"") -> 1140 | G3: =IF(Sheet2!L3<>"",Sheet2!L3,"") | J3: =IF(Sheet2!I3<>"",Sheet2!I3,"") -> https://item.taobao.com/item.htm?id=528647070337&skuId=6055794707724 | L3: =IF(Sheet2!J3<>"",Sheet2!J3,"") -> LM393DR贴片 (TI) | N3: =IF(Sheet2!E3<>"",Sheet2!E3,"") -> https://www.lcsc.com/product-detail/C67470.html | O3: =IF(Sheet2!G3<>"",Sheet2!G3,"") -> C67470 | P3: =IF(Sheet2!C3<>"",Sheet2!C3,"") -> LM393DR | Q3: ="https://github.com/Khuuxuanngoc/image_LK_ForWeb/blob/main/vnehciovn/"&A3&".jpg?raw=true" -> https://github.com/Khuuxuanngoc/image_LK_ForWeb/blob/main/vnehciovn/BA006FBA3B.jpg?raw=true
A4: =IF(Sheet2!H4<>"",Sheet2!H4,"") -> BA006BA9C1 | B4: =IF(Sheet2!A4<>"",Sheet2!A4,"") -> CONN-Audio-SMD-6P-3.5mm-4Ring-PJ-3420-A-C319102 | C4: Cái | D4: 0 | E4: 0 | F4: =IF(Sheet2!K4<>"",Sheet2!K4*3800,"") -> 4826 | G4: =IF(Sheet2!L4<>"",Sheet2!L4,"") | J4: =IF(Sheet2!I4<>"",Sheet2!I4,"") -> https://item.taobao.com/item.htm?id=742689790413 | L4: =IF(Sheet2!J4<>"",Sheet2!J4,"") | N4: =IF(Sheet2!E4<>"",Sheet2!E4,"") -> https://www.lcsc.com/product-detail/C319102.html?s_z=n_PJ-3420-A | O4: =IF(Sheet2!G4<>"",Sheet2!G4,"") -> C319102 | P4: =IF(Sheet2!C4<>"",Sheet2!C4,"") -> PJ-3420-A-C319102 | Q4: ="https://github.com/Khuuxuanngoc/image_LK_ForWeb/blob/main/vnehciovn/"&A4&".jpg?raw=true" -> https://github.com/Khuuxuanngoc/image_LK_ForWeb/blob/main/vnehciovn/BA006BA9C1.jpg?raw=true
A5: =IF(Sheet2!H5<>"",Sheet2!H5,"") -> BA0068DF4A | B5: =IF(Sheet2!A5<>"",Sheet2!A5,"") -> CONN-Ipex-RF_U.FL-BWU.FL-IPEX1 | C5: Cái | D5: 0 | E5: 0 | F5: =IF(Sheet2!K5<>"",Sheet2!K5*3800,"") -> 380 | G5: =IF(Sheet2!L5<>"",Sheet2!L5,"") -> 550 | J5: =IF(Sheet2!I5<>"",Sheet2!I5,"") -> https://item.taobao.com/item.htm?id=529673949109 | L5: =IF(Sheet2!J5<>"",Sheet2!J5,"") | N5: =IF(Sheet2!E5<>"",Sheet2!E5,"") -> https://www.lcsc.com/product-detail/C5137195.html?s_z=n_BAT%2520WIRELESS%2520BWU.FL-IPEX1 | O5: =IF(Sheet2!G5<>"",Sheet2!G5,"") -> C5137195 | P5: =IF(Sheet2!C5<>"",Sheet2!C5,"") -> BWU.FL-IPEX1 | Q5: ="https://github.com/Khuuxuanngoc/image_LK_ForWeb/blob/main/vnehciovn/"&A5&".jpg?raw=true" -> https://github.com/Khuuxuanngoc/image_LK_ForWeb/blob/main/vnehciovn/BA0068DF4A.jpg?raw=true
A6: =IF(Sheet2!H6<>"",Sheet2!H6,"") -> BA006FA63F | B6: =IF(Sheet2!A6<>"",Sheet2!A6,"") -> CONN-SMA-KE-90 | C6: Cái | D6: 0 | E6: 0 | F6: =IF(Sheet2!K6<>"",Sheet2!K6*3800,"") -> 2964 | G6: =IF(Sheet2!L6<>"",Sheet2!L6,"") | J6: =IF(Sheet2!I6<>"",Sheet2!I6,"") -> https://item.taobao.com/item.htm?id=529673697495&skuId=4051037650598 | L6: =IF(Sheet2!J6<>"",Sheet2!J6,"") -> SMA-KWE弯角内孔(90度弯) | N6: =IF(Sheet2!E6<>"",Sheet2!E6,"") | O6: =IF(Sheet2!G6<>"",Sheet2!G6,"") | P6: =IF(Sheet2!C6<>"",Sheet2!C6,"") -> SMA-KWE弯角内孔(90度弯) | Q6: ="https://github.com/Khuuxuanngoc/image_LK_ForWeb/blob/main/vnehciovn/"&A6&".jpg?raw=true" -> https://github.com/Khuuxuanngoc/image_LK_ForWeb/blob/main/vnehciovn/BA006FA63F.jpg?raw=true
A7: =IF(Sheet2!H7<>"",Sheet2!H7,"") -> BA006FB7C4 | B7: =IF(Sheet2!A7<>"",Sheet2!A7,"") -> CONN-SMA-KWE-90 | C7: Cái | D7: 0 | E7: 0 | F7: =IF(Sheet2!K7<>"",Sheet2!K7*3800,"") -> 2964 | G7: =IF(Sheet2!L7<>"",Sheet2!L7,"") | J7: =IF(Sheet2!I7<>"",Sheet2!I7,"") -> https://item.taobao.com/item.htm?id=529673697495&skuId=4051037650598 | L7: =IF(Sheet2!J7<>"",Sheet2!J7,"") -> SMA-KWE弯角内孔(90度弯) | N7: =IF(Sheet2!E7<>"",Sheet2!E7,"") | O7: =IF(Sheet2!G7<>"",Sheet2!G7,"") | P7: =IF(Sheet2!C7<>"",Sheet2!C7,"") -> SMA-KWE弯角内孔(90度弯) | Q7: ="https://github.com/Khuuxuanngoc/image_LK_ForWeb/blob/main/vnehciovn/"&A7&".jpg?raw=true" -> https://github.com/Khuuxuanngoc/image_LK_ForWeb/blob/main/vnehciovn/BA006FB7C4.jpg?raw=true
A8: =IF(Sheet2!H8<>"",Sheet2!H8,"") -> BA006BB3FF | B8: =IF(Sheet2!A8<>"",Sheet2!A8,"") -> CONN-SMD-EDGE-microbit-40P-Horizontal-Yellow | C8: Cái | D8: 0 | E8: 0 | F8: =IF(Sheet2!K8<>"",Sheet2!K8*3800,"") -> 18430 | G8: =IF(Sheet2!L8<>"",Sheet2!L8,"") | J8: =IF(Sheet2!I8<>"",Sheet2!I8,"") -> https://item.taobao.com/item.htm?id=599309272242&skuId=4187482509236 | L8: =IF(Sheet2!J8<>"",Sheet2!J8,"") -> 黄色 - 卧式 | N8: =IF(Sheet2!E8<>"",Sheet2!E8,"") -> https://item.taobao.com/item.htm?id=599309272242&skuId=4187482509236 | O8: =IF(Sheet2!G8<>"",Sheet2!G8,"") | P8: =IF(Sheet2!C8<>"",Sheet2!C8,"") -> mi-H-Yellow | Q8: ="https://github.com/Khuuxuanngoc/image_LK_ForWeb/blob/main/vnehciovn/"&A8&".jpg?raw=true" -> https://github.com/Khuuxuanngoc/image_LK_ForWeb/blob/main/vnehciovn/BA006BB3FF .jpg?raw=true
A9: =IF(Sheet2!H9<>"",Sheet2!H9,"") -> BA006BB774 | B9: =IF(Sheet2!A9<>"",Sheet2!A9,"") -> CONN-USB-B-Micro_C456008 | C9: Cái | D9: 0 | E9: 0 | F9: =IF(Sheet2!K9<>"",Sheet2!K9*3800,"") -> 646 | G9: =IF(Sheet2!L9<>"",Sheet2!L9,"") | J9: =IF(Sheet2!I9<>"",Sheet2!I9,"") -> https://item.taobao.com/item.htm?id=538147501606&skuId=5937546427295 | L9: =IF(Sheet2!J9<>"",Sheet2!J9,"") -> Micro-母座_牛角_无边 | N9: =IF(Sheet2!E9<>"",Sheet2!E9,"") -> https://www.lcsc.com/product-detail/C456008.html?s_z=n_USB-Micro | O9: =IF(Sheet2!G9<>"",Sheet2!G9,"") -> C456008 | P9: =IF(Sheet2!C9<>"",Sheet2!C9,"") -> MICRO-4P-DIP | Q9: ="https://github.com/Khuuxuanngoc/image_LK_ForWeb/blob/main/vnehciovn/"&A9&".jpg?raw=true" -> https://github.com/Khuuxuanngoc/image_LK_ForWeb/blob/main/vnehciovn/BA006BB774.jpg?raw=true
A10: =IF(Sheet2!H10<>"",Sheet2!H10,"") -> BA0068C9EC | B10: =IF(Sheet2!A10<>"",Sheet2!A10,"") -> CONN-USB_C_Receptacle_USB2.0_16P | C10: Cái | D10: 0 | E10: 0 | F10: =IF(Sheet2!K10<>"",Sheet2!K10*3800,"") -> 646 | G10: =IF(Sheet2!L10<>"",Sheet2!L10,"") -> 870 | J10: =IF(Sheet2!I10<>"",Sheet2!I10,"") -> https://item.taobao.com/item.htm?id=573090887123&skuId=5770750381254 | L10: =IF(Sheet2!J10<>"",Sheet2!J10,"") -> Type-C母座_16P_4脚插板_黑色 | N10: =IF(Sheet2!E10<>"",Sheet2!E10,"") -> https://www.lcsc.com/product-detail/C393939.html | O10: =IF(Sheet2!G10<>"",Sheet2!G10,"") -> C393939 | P10: =IF(Sheet2!C10<>"",Sheet2!C10,"") -> USB_C_16P | Q10: ="https://github.com/Khuuxuanngoc/image_LK_ForWeb/blob/main/vnehciovn/"&A10&".jpg?raw=true" -> https://github.com/Khuuxuanngoc/image_LK_ForWeb/blob/main/vnehciovn/BA0068C9EC.jpg?raw=true
A11: =IF(Sheet2!H11<>"",Sheet2!H11,"") -> BA0089F247 | B11: =IF(Sheet2!A11<>"",Sheet2!A11,"") -> DIOD_DO-220AA-SMP-SS1P3L-M3/84A-30V_1.5A | C11: Cái | D11: 0 | E11: 0 | F11: =IF(Sheet2!K11<>"",Sheet2!K11*3800,"") -> 1444 | G11: =IF(Sheet2!L11<>"",Sheet2!L11,"") | J11: =IF(Sheet2!I11<>"",Sheet2!I11,"") -> https://item.taobao.com/item.htm?id=1028490266957 | L11: =IF(Sheet2!J11<>"",Sheet2!J11,"") | N11: =IF(Sheet2!E11<>"",Sheet2!E11,"") -> https://www.lcsc.com/product-detail/C2875475.html?s_z=n_ss1p3L | O11: =IF(Sheet2!G11<>"",Sheet2!G11,"") -> C2875475 | P11: =IF(Sheet2!C11<>"",Sheet2!C11,"") -> SS1P3L-M3/84A | Q11: ="https://github.com/Khuuxuanngoc/image_LK_ForWeb/blob/main/vnehciovn/"&A11&".jpg?raw=true" -> https://github.com/Khuuxuanngoc/image_LK_ForWeb/blob/main/vnehciovn/BA0089F247.jpg?raw=true
A12: =IF(Sheet2!H12<>"",Sheet2!H12,"") -> BA0068D64B | B12: =IF(Sheet2!A12<>"",Sheet2!A12,"") -> DIOD_SS34_SMA_40V_3A | C12: Cái | D12: 0 | E12: 0 | F12: =IF(Sheet2!K12<>"",Sheet2!K12*3800,"") -> 760 | G12: =IF(Sheet2!L12<>"",Sheet2!L12,"") -> 690 | J12: =IF(Sheet2!I12<>"",Sheet2!I12,"") -> https://item.taobao.com/item.htm?id=545422120963 | L12: =IF(Sheet2!J12<>"",Sheet2!J12,"") | N12: =IF(Sheet2!E12<>"",Sheet2!E12,"") -> https://www.lcsc.com/product-detail/C8678.html | O12: =IF(Sheet2!G12<>"",Sheet2!G12,"") -> C8678 | P12: =IF(Sheet2!C12<>"",Sheet2!C12,"") -> SS34 | Q12: ="https://github.com/Khuuxuanngoc/image_LK_ForWeb/blob/main/vnehciovn/"&A12&".jpg?raw=true" -> https://github.com/Khuuxuanngoc/image_LK_ForWeb/blob/main/vnehciovn/BA0068D64B.jpg?raw=true
A13: =IF(Sheet2!H13<>"",Sheet2!H13,"") -> BA0068C41F | B13: =IF(Sheet2!A13<>"",Sheet2!A13,"") -> Diode-TVS-LESD5D5.0CT1G-SOD-523 | C13: Cái | D13: 0 | E13: 0 | F13: =IF(Sheet2!K13<>"",Sheet2!K13*3800,"") -> 190 | G13: =IF(Sheet2!L13<>"",Sheet2!L13,"") -> 380 | J13: =IF(Sheet2!I13<>"",Sheet2!I13,"") -> https://item.taobao.com/item.htm?id=893986185841 | L13: =IF(Sheet2!J13<>"",Sheet2!J13,"") | N13: =IF(Sheet2!E13<>"",Sheet2!E13,"") -> https://www.lcsc.com/product-detail/C5199850.html?s_z=n_LESD5D5.0CT1G | O13: =IF(Sheet2!G13<>"",Sheet2!G13,"") -> C5199850 | P13: =IF(Sheet2!C13<>"",Sheet2!C13,"") -> LESD5D5.0CT1G | Q13: ="https://github.com/Khuuxuanngoc/image_LK_ForWeb/blob/main/vnehciovn/"&A13&".jpg?raw=true" -> https://github.com/Khuuxuanngoc/image_LK_ForWeb/blob/main/vnehciovn/BA0068C41F.jpg?raw=true
... A800: =IF(Sheet2!H800<>"",Sheet2!H800,"") | B800: =IF(Sheet2!A800<>"",Sheet2!A800,"") | C800: Cái | D800: 0 | E800: 0 | F800: =IF(Sheet2!K800<>"",Sheet2!K800*3800,"") | G800: =IF(Sheet2!L800<>"",Sheet2!L800,"") | J800: =IF(Sheet2!I800<>"",Sheet2!I800,"") | L800: =IF(Sheet2!J800<>"",Sheet2!J800,"") | N800: =IF(Sheet2!E800<>"",Sheet2!E800,"") | O800: =IF(Sheet2!G800<>"",Sheet2!G800,"") | P800: =IF(Sheet2!C800<>"",Sheet2!C800,"") | Q800: ="https://github.com/Khuuxuanngoc/image_LK_ForWeb/blob/main/vnehciovn/"&A800&".jpg?raw=true" -> https://github.com/Khuuxuanngoc/image_LK_ForWeb/blob/main/vnehciovn/.jpg?raw=true
